<?xml version="1.0"?>
<robot name="john">

  <material name="black"><color rgba="0 0 0 1"/></material>
  <material name="grey"><color rgba="0.5 0.5 0.5 1"/></material>

<link name="base_footprint"/>
<joint name="base_footprint_joint" type="fixed">
  <parent link="base_footprint"/>
  <child link="base_link"/>
  <origin xyz="0 0 0.06" rpy="0 0 0"/>
</joint>

  <link name="base_link">
    <collision>
      <geometry><box size="0.2775 0.20 0.06"/></geometry>
    </collision>
    <visual>
      <geometry><box size="0.2775 0.20 0.06"/></geometry>
      <material name="grey"/>
    </visual>
    <inertial>
      <mass value="2.0"/>
      <inertia ixx="0.01" ixy="0" ixz="0" iyy="0.01" iyz="0" izz="0.01"/>
    </inertial>
  </link>

  <link name="front_left_wheel">
    <collision><geometry><cylinder length="0.05" radius="0.06"/></geometry></collision>
    <visual><geometry><cylinder length="0.05" radius="0.06"/></geometry><material name="black"/></visual>
    <inertial>
      <mass value="0.5"/><inertia ixx="0.001" ixy="0" ixz="0" iyy="0.001" iyz="0" izz="0.001"/>
    </inertial>
  </link>
  <joint name="front_left_wheel_joint" type="continuous">
    <parent link="base_link"/><child link="front_left_wheel"/>
    <origin xyz="0.10 0.12 0" rpy="1.57 0 0"/><axis xyz="0 0 1"/>
  </joint>

  <link name="front_right_wheel">
    <collision><geometry><cylinder length="0.05" radius="0.06"/></geometry></collision>
    <visual><geometry><cylinder length="0.05" radius="0.06"/></geometry><material name="black"/></visual>
    <inertial>
      <mass value="0.5"/><inertia ixx="0.001" ixy="0" ixz="0" iyy="0.001" iyz="0" izz="0.001"/>
    </inertial>
  </link>
  <joint name="front_right_wheel_joint" type="continuous">
    <parent link="base_link"/><child link="front_right_wheel"/>
    <origin xyz="0.10 -0.12 0" rpy="1.57 0 0"/><axis xyz="0 0 1"/>
  </joint>

  <link name="rear_left_wheel">
    <collision><geometry><cylinder length="0.05" radius="0.06"/></geometry></collision>
    <visual><geometry><cylinder length="0.05" radius="0.06"/></geometry><material name="black"/></visual>
    <inertial>
      <mass value="0.5"/><inertia ixx="0.001" ixy="0" ixz="0" iyy="0.001" iyz="0" izz="0.001"/>
    </inertial>
  </link>
  <joint name="rear_left_wheel_joint" type="continuous">
    <parent link="base_link"/><child link="rear_left_wheel"/>
    <origin xyz="-0.10 0.12 0" rpy="1.57 0 0"/><axis xyz="0 0 1"/>
  </joint>

  <link name="rear_right_wheel">
    <collision><geometry><cylinder length="0.05" radius="0.06"/></geometry></collision>
    <visual><geometry><cylinder length="0.05" radius="0.06"/></geometry><material name="black"/></visual>
    <inertial>
      <mass value="0.5"/><inertia ixx="0.001" ixy="0" ixz="0" iyy="0.001" iyz="0" izz="0.001"/>
    </inertial>
  </link>
  <joint name="rear_right_wheel_joint" type="continuous">
    <parent link="base_link"/><child link="rear_right_wheel"/>
    <origin xyz="-0.10 -0.12 0" rpy="1.57 0 0"/><axis xyz="0 0 1"/>
  </joint>

  <link name="lidar_link">
    <collision><geometry><cylinder length="0.04" radius="0.035"/></geometry></collision>
    <visual><geometry><cylinder length="0.04" radius="0.035"/></geometry><material name="black"/></visual>
    <inertial>
      <mass value="0.1"/><inertia ixx="0.001" ixy="0" ixz="0" iyy="0.001" iyz="0" izz="0.001"/>
    </inertial>
  </link>
  <joint name="lidar_joint" type="fixed">
    <parent link="base_link"/>
    <child link="lidar_link"/>
    <origin xyz="0.10 0.08 0.08" rpy="0 0 0"/>
  </joint>

<link name="imu_link">
  <inertial>
    <mass value="0.01"/>
    <inertia ixx="0.00001" ixy="0" ixz="0" iyy="0.00001" iyz="0" izz="0.00001"/>
  </inertial>
</link>

<joint name="imu_joint" type="fixed">
  <parent link="base_link"/>
  <child link="imu_link"/>
  <origin xyz="0 0 0.03" rpy="0 0 0"/>
</joint>

  <gazebo>
    <plugin name="skid_steer_drive" filename="libgazebo_ros_diff_drive.so">
      <ros><namespace>/</namespace></ros>
      <num_wheel_pairs>2</num_wheel_pairs>
      <left_joint>front_left_wheel_joint</left_joint>
      <left_joint>rear_left_wheel_joint</left_joint>
      <right_joint>front_right_wheel_joint</right_joint>
      <right_joint>rear_right_wheel_joint</right_joint>
      <wheel_separation>0.2775</wheel_separation>
      <wheel_diameter>0.12</wheel_diameter>
      <publish_odom>true</publish_odom>
      <publish_odom_tf>true</publish_odom_tf>
      <publish_wheel_tf>true</publish_wheel_tf>
      <odometry_frame>odom</odometry_frame>
      <robot_base_frame>base_link</robot_base_frame>
    </plugin>
  </gazebo>

<gazebo reference="imu_link">
  <sensor name="imu_sensor" type="imu">
    <always_on>true</always_on>
    <update_rate>100</update_rate>
    <plugin name="imu_plugin" filename="libgazebo_ros_imu_sensor.so">
      <ros>
        <remapping>~/out:=imu</remapping>
      </ros>
      <initial_orientation_as_reference>false</initial_orientation_as_reference>
    </plugin>
  </sensor>
</gazebo>

  <gazebo reference="lidar_link">
    <sensor name="lidar" type="ray">
      <always_on>true</always_on>
      <visualize>true</visualize>
      <update_rate>10</update_rate>
      <ray>
        <scan>
          <horizontal>
            <samples>360</samples>
            <min_angle>0.0</min_angle>
            <max_angle>6.28</max_angle>
          </horizontal>
        </scan>
        <range>
          <min>0.12</min>
          <max>12.0</max>
        </range>
      </ray>
      <plugin name="bytes_laser" filename="libgazebo_ros_ray_sensor.so">
        <ros>
          <remapping>~/out:=scan</remapping>
        </ros>
        <output_type>sensor_msgs/LaserScan</output_type>
        <frame_name>lidar_link</frame_name>
      </plugin>
    </sensor>
  </gazebo>

</robot>
